<?xml version="1.0" encoding="utf-8"?>
<!-- This URDF was automatically created by SolidWorks to URDF Exporter! Originally created by Stephen Brawner (brawner@gmail.com) 
     Commit Version: 1.6.0-4-g7f85cfe  Build Version: 1.6.7995.38578
     For more information, please see http://wiki.ros.org/sw_urdf_exporter -->
<robot xmlns:xacro="http://www.ros.org/wiki/xacro" name="fred_montagem">


    <material name="blue">
      <color rgba="0 0 0.8 1"/>
    </material>
  
    <material name="black">
      <color rgba="0.37 0.37 0.37 1"/>
    </material>
  
    <material name="white">
      <color rgba="0.79 0.90 0.91 1"/>
    </material>
 
  
<!-- !_____________________ BASE OF THE ROBOT -> LINK _____________________ -->
  <link name="base_link">
    <inertial>  <!-- *Define the inertial properties of the link -->
      <origin
        xyz="0.00139187403858163 0.0661307685643301 0.00395945537614263"
        rpy="0 0 0" />
      <mass
        value="4.63143329848068" />
      <inertia
        ixx="0.0356984612583256"
        ixy="-3.70847488075032E-06"
        ixz="-5.00982880058767E-05"
        iyy="0.0474801044455017"
        iyz="6.61023819591993E-05"
        izz="0.0136093829558188" />
    </inertial>
    <visual> <!-- *Define the visual properties of the link -->
      <origin
        xyz="0 0 0"
        rpy="0 0 0" /> <!-- *Define the position in relation of the base_link -->
      <geometry> <!-- *Define the geometry information --> 
        <mesh filename="package://fred_montagem/meshes/base_link.STL" /> <!-- *The mesh file used for visualization of the link -->
      </geometry>
      <material name="white"> <!-- *Define the material properties of the link -->
        <color rgba="0.752941176470588 0.752941176470588 0.752941176470588 1" /> <!-- *The RGBA color values (red, green, blue, alpha) -->
      </material>
    </visual>
    <collision> <!-- *Define the collision properties of the link -->
      <origin
        xyz="0 0 0"
        rpy="0 0 0" />
      <geometry>
        <mesh
          filename="package://fred_montagem/meshes/base_link.STL" /> <!-- *The mesh file used for collision detection of the link -->
      </geometry>
    </collision>
  </link>


  <!-- !______________________ SENSORS INFORMATION ___________________________-->
  
  <!-- ! LIDAR SENSOR ___________________________-->
  
  <link name="lidar_link">
  <!-- *Link description -->

    <!-- *Definition of LIDAR sensor -->
    <sensor name="lidar_sensor" type="ray">
      <pose xyz="0.225 0 0.07" rpy="0 0 0" /> <!-- *Sensor position and orientation -->
      <visualize>true</visualize> <!-- *Sensor visualization -->
      <update_rate>10</update_rate> <!-- *Sensor update rate (10 Hz) -->

      <!-- *LIDAR scan settings -->
      <ray>
        <scan>
          <horizontal>
            <samples>360</samples> <!-- *Number of scan samples (360) -->
            <resolution>1</resolution> <!-- *Angular resolution of the scan (1 radian) -->
            <min_angle>-1.5708</min_angle> <!-- *Minimum scan angle (-90 degrees) -->
            <max_angle>1.5708</max_angle> <!-- *Maximum scan angle (90 degrees) -->
          </horizontal>
        </scan>

        <!-- *LIDAR range settings -->
        <range>
          <min>0.01</min> <!-- *Minimum range distance (0.01 meters) -->
          <max>12.0</max> <!-- *Maximum range distance (12.0 meters) -->
          <resolution>0.01</resolution> <!-- *Range resolution (0.01 meters) -->
        </range>
      </ray>
    </sensor>
  </link>

  <joint name="lidar_joint" type="fixed">
    <origin xyz="0 0.18 0.187" rpy="0 0 0" />
    <parent link="base_link" />
    <child link="lidar_link" />

    <!-- *Definition of LIDAR sensor -->
    <sensor name="lidar_sensor" type="ray">
      <pose xyz=" 0 0.225 0.07" rpy="0 0 0" /> <!-- *Sensor position and orientation -->
      <visualize>true</visualize> <!-- *Sensor visualization -->
      <update_rate>10</update_rate> <!-- *Sensor update rate (10 Hz) -->

      <!-- *LIDAR scan settings -->
      <ray>
        <scan>
          <horizontal>
            <samples>360</samples> <!-- *Number of scan samples (360) -->
            <resolution>1</resolution> <!-- *Angular resolution of the scan (1 radian) -->
            <min_angle>-1.5708</min_angle> <!-- *Minimum scan angle (-90 degrees) -->
            <max_angle>1.5708</max_angle> <!-- *Maximum scan angle (90 degrees) -->
          </horizontal>
        </scan>

        <!-- *LIDAR range settings -->
        <range>
          <min>0.01</min> <!-- *Minimum range distance (0.01 meters) -->
          <max>12.0</max> <!-- *Maximum range distance (12.0 meters) -->
          <resolution>0.01</resolution> <!-- *Range resolution (0.01 meters) -->
        </range>
      </ray>
    </sensor>
  </joint>

  <!-- !______________________ WHEELS INFORMATION ___________________________-->
  
  <!-- ! WHEEL 1 ___________________________-->

  <link
    name="roda1_link">
    <inertial>
      <origin
        xyz="0 -1.38777878078145E-17 -0.00141323710439914"
        rpy="0 0 0" />
      <mass
        value="0.429989283650456" />
      <inertia
        ixx="0.000697974605354243"
        ixy="-1.35525271560688E-20"
        ixz="-4.20771292679119E-20"
        iyy="0.000697974605354243"
        iyz="-4.01268310786857E-19"
        izz="0.00133072022796708" />
    </inertial>
    <visual>
      <origin
        xyz="0 0 0"
        rpy="0 0 0" />
      <geometry>
        <mesh
          filename="package://fred_montagem/meshes/roda1.STL" />
      </geometry>
      <material
        name="black">
        <color
          rgba="0.792156862745098 0.819607843137255 0.933333333333333 1" />
      </material>
    </visual>
    <collision>
      <origin
        xyz="0 0 0"
        rpy="0 0 0" />
      <geometry>
        <mesh
          filename="package://fred_montagem/meshes/roda1.STL" />
      </geometry>
    </collision>
  </link>
  <joint
    name="roda1"
    type="continuous">
    <origin
      xyz="0.14881 0.113 0.025"
      rpy="1.5708 -1.3493 1.5708" />
    <parent
      link="base_link" />
    <child
      link="roda1_link" />
    <axis xyz="0 0 1" rpy="0 0 0" />

  </joint>
  
  
  
  <!-- ! WHEEL 2 ___________________________--> 
  <link
    name="roda2">
    <inertial>
      <origin
        xyz="0 0 -0.00141323710439917"
        rpy="0 0 0" />
      <mass
        value="0.429989283650456" />
      <inertia
        ixx="0.000697974605354243"
        ixy="0"
        ixz="4.17648288400282E-20"
        iyy="0.000697974605354243"
        iyz="-3.97310150637262E-19"
        izz="0.00133072022796708" />
    </inertial>
    <visual>
      <origin
        xyz="0 0 0"
        rpy="0 0 0" />
      <geometry>
        <mesh
          filename="package://fred_montagem/meshes/roda2.STL" />
      </geometry>
      <material
        name="black">
        <color
          rgba="0.792156862745098 0.819607843137255 0.933333333333333 1" />
      </material>
    </visual>
    <collision>
      <origin
        xyz="0 0 0"
        rpy="0 0 0" />
      <geometry>
        <mesh
          filename="package://fred_montagem/meshes/roda2.STL" />
      </geometry>
    </collision>
  </link>
  <joint
    name="roda2"
    type="continuous">
    <origin
      xyz="-0.14881 0.113 0.025"
      rpy="1.5708 1.3493 -1.5708" />
    <parent
      link="base_link" />
    <child
      link="roda2" />
    <axis xyz="0 0 1" rpy="0 0 0" />

  </joint>
  

  <!-- ! WHEEL 3 ___________________________-->
  <link
    name="roda3">
    <inertial>
      <origin
        xyz="2.77555756156289E-17 6.93889390390723E-18 -0.0014132371043992"
        rpy="0 0 0" />
      <mass
        value="0.429989283650456" />
      <inertia
        ixx="0.000697974605354243"
        ixy="0"
        ixz="1.40369272626023E-19"
        iyy="0.000697974605354243"
        iyz="2.38922098829457E-20"
        izz="0.00133072022796708" />
    </inertial>
    <visual>
      <origin
        xyz="0 0 0"
        rpy="0 0 0" />
      <geometry>
        <mesh
          filename="package://fred_montagem/meshes/roda3.STL" />
      </geometry>
      <material
        name="black">
        <color
          rgba="0.792156862745098 0.819607843137255 0.933333333333333 1" />
      </material>
    </visual>
    <collision>
      <origin
        xyz="0 0 0"
        rpy="0 0 0" />
      <geometry>
        <mesh
          filename="package://fred_montagem/meshes/roda3.STL" />
      </geometry>
    </collision>
  </link>
  <joint
    name="roda3"
    type="continuous">
    <origin
      xyz="0.14881 -0.113 0.025"
      rpy="1.5708 0.72582 1.5708" />
    <parent
      link="base_link" />
    <child
      link="roda3" />
    <axis xyz="0 0 1" rpy="0 0 0" />

  </joint>
  
  
  <!-- ! WHEEL 4 ___________________________-->
  <link
    name="roda4">
    <inertial>
      <origin
        xyz="-4.16333634234434E-17 6.93889390390723E-18 -0.00141323710439917"
        rpy="0 0 0" />
      <mass
        value="0.429989283650456" />
      <inertia
        ixx="0.000697974605354243"
        ixy="-2.71050543121376E-20"
        ixz="-1.37211286325669E-19"
        iyy="0.000697974605354243"
        iyz="1.23583139761425E-20"
        izz="0.00133072022796708" />
    </inertial>
    <visual>
      <origin
        xyz="0 0 0"
        rpy="0 0 0" />
      <geometry>
        <mesh
          filename="package://fred_montagem/meshes/roda4.STL" />
      </geometry>
      <material
        name="black">
        <color
          rgba="0.792156862745098 0.819607843137255 0.933333333333333 1" />
      </material>
    </visual>
    <collision>
      <origin
        xyz="0 0 0"
        rpy="0 0 0" />
      <geometry>
        <mesh
          filename="package://fred_montagem/meshes/roda4.STL" />
      </geometry>
    </collision>
  </link>
  <joint
    name="roda4"
    type="continuous">
    <origin
      xyz="-0.14881 -0.113 0.025"
      rpy="1.5708 -0.72582 -1.5708" />
    <parent
      link="base_link" />
    <child
      link="roda4" />
    <axis xyz="0 0 1" rpy="0 0 0" />


  </joint>
</robot>